<?xml version="1.0"?>
<robot name="myfirst" xmlns:xacro="http://www.ros.org/wiki/xacro">

  <link name="base_link">
    <visual>
      <geometry>
        <box size="0.8 0.5 0.06"/>
      </geometry>
      <material name="metal">
        <color rgba="0 0 0 1.0"/>
      </material>
    </visual>
    <collision>
      <geometry>
        <box size="0.8 0.5 0.06"/>
      </geometry>
    </collision>
    <inertial>
      <mass value="10"/>
      <inertia ixx="0.0" ixy="0.0" ixz="0.0" izz="0.0" iyy="0.0" iyz="0.0" />
    </inertial>
  </link>

  <link name="left_wheel_center">
    <visual>
      <geometry>
        <cylinder length="0.04" radius="0.12"/>
      </geometry>
      <origin rpy="0 0 0" xyz="0 0 0"/>
    </visual>

  <collision>
    <geometry>
      <cylinder length="0.04" radius="0.12"/>
    </geometry>
    <origin rpy="0 0 0" xyz="0 0 0"/>
  </collision>

  <inertial>
    <mass value="0.3"/>
    <inertia ixx="0.0" ixy="0.0" ixz="0.0" iyy="0.0" iyz="0.0" izz="0.0"/>
  </inertial>
  </link>



  <joint name="left_wheel_center_to_body" type="continuous">
    <parent link="base_link"/>
    <child link="left_wheel_center"/>
    <origin xyz="0 0.26 0" rpy="1.57 1.57 0"/>
    <axis xyz="0 0 1"/>
  </joint>

</robot>
