<?xml version="1.0"?>

<robot name="bosmat_low" xmlns:xacro="http://www.ros.org/wiki/xacro">

	<material name="black">
		<color rgba="0 0 0 1"/>
	</material>

	<material name="white">
		<color rgba="1 1 1 1"/>
	</material>

	<material name="red">
		<color rgba="1 0 0 1"/>
	</material>

	<material name="green">
		<color rgba="0 1 0 1"/>
	</material>

	<material name="blue">
		<color rgba="0 0 1 1"/>
	</material>

	<material name="magenta">
		<color rgba="1 0 1 1"/>
	</material>

	<material name="cyan">
		<color rgba="0 1 1 1"/>
	</material>

	<material name="yellow">
		<color rgba="1 1 0 1"/>
	</material>


	<link name="base_link">
		<visual>
			<origin xyz="-0.45 -0.23 -0.05" rpy="1.5707963268 0 1.5707963268" />
			<geometry>
				<mesh filename="package://bosmat_description/meshes/low_detail/robot_base.STL" scale="0.001 0.001 0.001"/>
			</geometry>
			<material name="white"/>
		</visual>

		<collision>
			<origin xyz="-0.45 -0.23 0" rpy="1.5707963268 0 1.5707963268" />
			<geometry>
				<mesh filename="package://bosmat_description/meshes/low_detail/robot_base.STL" scale="0.001 0.001 0.001"/>
			</geometry>
		</collision>

		<inertial>
		  <mass value="10.0"/>
		  <inertia ixx="1.0" iyy="1.0" izz="1.0" ixy="0.0" ixz="0.0" iyz="0.0"/>
		</inertial>
	</link>

	<link name="left_center_wheel">
		<visual>
			<geometry>
				<cylinder length="0.05" radius="0.1"/>
			</geometry>
			<origin rpy="1.5707963268 0 0" xyz="0 0 0"/>
			<material name="green"/>
		</visual>

		<collision>
			<geometry>
				<cylinder length="0.05" radius="0.1"/>
			</geometry>
			<origin rpy="1.5707963268 0 0" xyz="0.23 0 0"/>
		</collision>

		<inertial>
			<mass value="0.5"/>
			<inertia ixx="0.1" iyy="0.1" izz="0.1" ixy="0.0" ixz="0.0" iyz="0.0"/>
		</inertial>
	</link>

	<joint name="left_center_wheel_to_base_link" type="continuous">
		<parent link="base_link"/>
		<child link="left_center_wheel"/>
		<origin xyz="0 0.27 0" rpy="0 0 0"/>
		<axis xyz="0 1 0"/>
	</joint>

    <link name="left_front_wheel">
		<visual>
			<geometry>
				<cylinder length="0.05" radius="0.1"/>
			</geometry>
			<origin rpy="1.5707963268 0 0" xyz="0 0 0"/>
			<material name="green"/>
		</visual>

		<collision>
			<geometry>
				<cylinder length="0.05" radius="0.1"/>
			</geometry>
			<origin rpy="1.5707963268 0 0" xyz="0.23 0 0"/>
		</collision>

		<inertial>
			<mass value="0.5"/>
			<inertia ixx="0.1" iyy="0.1" izz="0.1" ixy="0.0" ixz="0.0" iyz="0.0"/>
		</inertial>
	</link>

    <joint name="left_front_wheel_to_base_link" type="continuous">
		<parent link="base_link"/>
		<child link="left_front_wheel"/>
		<origin xyz="0.345 0.27 0" rpy="0 0 0"/>
		<axis xyz="0 1 0"/>
    </joint>

    <link name="left_back_wheel">
		<visual>
			<geometry>
				<cylinder length="0.05" radius="0.1"/>
			</geometry>
			<origin rpy="1.5707963268 0 0" xyz="0 0 0"/>
			<material name="green"/>
		</visual>

		<collision>
			<geometry>
				<cylinder length="0.05" radius="0.1"/>
			</geometry>
			<origin rpy="1.5707963268 0 0" xyz="0.23 0 0"/>
		</collision>

		<inertial>
			<mass value="0.5"/>
			<inertia ixx="0.1" iyy="0.1" izz="0.1" ixy="0.0" ixz="0.0" iyz="0.0"/>
		</inertial>
	</link>

    <joint name="left_back_wheel_to_base_link" type="continuous">
		<parent link="base_link"/>
		<child link="left_back_wheel"/>
		<origin xyz="-0.345 0.27 0" rpy="0 0 0"/>
		<axis xyz="0 1 0"/>
    </joint>

<link name="right_center_wheel">
		<visual>
			<geometry>
				<cylinder length="0.05" radius="0.1"/>
			</geometry>
			<origin rpy="1.5707963268 0 0" xyz="0 0 0"/>
			<material name="green"/>
		</visual>

		<collision>
			<geometry>
				<cylinder length="0.05" radius="0.1"/>
			</geometry>
			<origin rpy="1.5707963268 0 0" xyz="0.23 0 0"/>
		</collision>

		<inertial>
			<mass value="0.5"/>
			<inertia ixx="0.1" iyy="0.1" izz="0.1" ixy="0.0" ixz="0.0" iyz="0.0"/>
		</inertial>
	</link>

	<joint name="right_center_wheel_to_base_link" type="continuous">
		<parent link="base_link"/>
		<child link="right_center_wheel"/>
		<origin xyz="0 -0.27 0" rpy="0 0 0"/>
		<axis xyz="0 1 0"/>
	</joint>

    <link name="right_front_wheel">
		<visual>
			<geometry>
				<cylinder length="0.05" radius="0.1"/>
			</geometry>
			<origin rpy="1.5707963268 0 0" xyz="0 0 0"/>
			<material name="green"/>
		</visual>

		<collision>
			<geometry>
				<cylinder length="0.05" radius="0.1"/>
			</geometry>
			<origin rpy="1.5707963268 0 0" xyz="0.23 0 0"/>
		</collision>

		<inertial>
			<mass value="0.5"/>
			<inertia ixx="0.1" iyy="0.1" izz="0.1" ixy="0.0" ixz="0.0" iyz="0.0"/>
		</inertial>
	</link>

    <joint name="right_front_wheel_to_base_link" type="continuous">
		<parent link="base_link"/>
		<child link="right_front_wheel"/>
		<origin xyz="0.345 -0.27 0" rpy="0 0 0"/>
		<axis xyz="0 1 0"/>
    </joint>

    <link name="right_back_wheel">
		<visual>
			<geometry>
				<cylinder length="0.05" radius="0.1"/>
			</geometry>
			<origin rpy="1.5707963268 0 0" xyz="0 0 0"/>
			<material name="green"/>
		</visual>

		<collision>
			<geometry>
				<cylinder length="0.05" radius="0.1"/>
			</geometry>
			<origin rpy="1.5707963268 0 0" xyz="0.23 0 0"/>
		</collision>

		<inertial>
			<mass value="0.5"/>
			<inertia ixx="0.1" iyy="0.1" izz="0.1" ixy="0.0" ixz="0.0" iyz="0.0"/>
		</inertial>
	</link>

    <joint name="right_back_wheel_to_base_link" type="continuous">
		<parent link="base_link"/>
		<child link="right_back_wheel"/>
		<origin xyz="-0.345 -0.27 0" rpy="0 0 0"/>
		<axis xyz="0 1 0"/>
    </joint>

	<link name="shiri_body">
		<visual>
			<origin xyz="0 -0.03 0" rpy="1.5707963268 0 1.5707963268" />
			<geometry>
				<mesh filename="package://bosmat_description/meshes/low_detail/shiri_body_low_detail.STL"/>
			</geometry>
			<material name="cyan"/>
		</visual>

		<inertial>
			<mass value="2.0"/>
			<inertia ixx="0.1" iyy="0.1" izz="0.1" ixy="0.0" ixz="0.0" iyz="0.0"/>
		</inertial>
	</link>

    <joint name="shiri_body_to_base_link" type="prismatic">
		<parent link="base_link"/>
		<child link="shiri_body"/>
		<origin xyz="0.35 0 0" rpy="0 0 0"/>
		<limit effort="1000.0" velocity="1.0" lower="-0.2" upper="0"/>
		<axis xyz="1 0 0"/>
    </joint>

	<link name="shiri_left_finger">
		<visual>
			<origin xyz="0.105 -0.03 -0.03" rpy="0 -1.5707963268 0" />
			<geometry>
				<mesh filename="package://bosmat_description/meshes/low_detail/shiri_finger_low_detail.STL"/>
			</geometry>
			<material name="magenta"/>
		</visual>

		<collision>
			<geometry>
				<mesh filename="package://bosmat_description/meshes/low_detail/shiri_finger_low_detail.STL"/>
			</geometry>
			<origin xyz="0.105 -0.03 -0.03" rpy="0 -1.5707963268 0" />
		</collision>

		<inertial>
		  <mass value="0.1"/>
		  <inertia ixx="0.01" iyy="0.01" izz="0.01" ixy="0.0" ixz="0.0" iyz="0.0"/>
		</inertial>
	</link>

    <joint name="shiri_left_finger_to_body" type="prismatic">
		<parent link="shiri_body"/>
		<child link="shiri_left_finger"/>
		<origin xyz="0.18 0.03 0.36" rpy="0 0 0"/>
		<limit effort="1000.0" velocity="1.0" lower="0" upper="0.03"/>
		<axis xyz="0 1 0"/>
    </joint>

	<link name="shiri_right_finger">
		<visual>
			<origin xyz="0.105 -0.03 -0.03" rpy="0 -1.5707963268 0" />
			<geometry>
				<mesh filename="package://bosmat_description/meshes/low_detail/shiri_finger_low_detail.STL"/>
			</geometry>
			<material name="magenta"/>
		</visual>

		<collision>
			<geometry>
				<mesh filename="package://bosmat_description/meshes/low_detail/shiri_finger_low_detail.STL"/>
			</geometry>
			<origin xyz="0.105 -0.03 -0.03" rpy="0 -1.5707963268 0" />
		</collision>

		<inertial>
		  <mass value="0.1"/>
		  <inertia ixx="0.01" iyy="0.01" izz="0.01" ixy="0.0" ixz="0.0" iyz="0.0"/>
		</inertial>
	</link>

    <joint name="shiri_right_finger_to_body" type="prismatic">
		<parent link="shiri_body"/>
		<child link="shiri_right_finger"/>
		<origin xyz="0.18 -0.03 0.36" rpy="3.1415926536 0 0"/>
		<limit effort="1000.0" velocity="1.0" lower="0" upper="0.03"/>
		<axis xyz="0 1 0"/>
    </joint>

	<link name="astra_camera">
		<visual>
			<origin xyz="0 0 0" rpy="-1.5707963268 0 1.5707963268" />
			<geometry>
				<box size="0.1 0.1 0.1"/>
			</geometry>
			<material name="blue"/>
		</visual>

		<inertial>
		  <mass value="0.1"/>
		  <inertia ixx="0.01" iyy="0.01" izz="0.01" ixy="0.0" ixz="0.0" iyz="0.0"/>
		</inertial>
	</link>

    <joint name="astra_camera_to_base_link" type="fixed">
		<parent link="base_link"/>
		<child link="astra_camera"/>
		<origin xyz="-0.3 0 0.7" rpy="-1.6707963268 0 -1.5707963268"/>
    </joint>

<!-- gazebo pluings -->

<!--
<gazebo reference="base_link">
  <mu1>0.5</mu1>
  <mu2>0.5</mu2>
  <material>Gazebo/White</material>
</gazebo>

<gazebo reference="left_back_wheel">
  <mu1>1</mu1>
  <mu2>1</mu2>
  <kp>100.0</kp>
  <kd>100.0</kd>
  <minDepth>0.001</minDepth>
  <maxVel>1</maxVel>
  <material>Gazebo/Black</material>
</gazebo>

<gazebo reference="left_center_wheel">
  <mu1>1</mu1>
  <mu2>1</mu2>
  <kp>100.0</kp>
  <kd>100.0</kd>
  <minDepth>0.001</minDepth>
  <maxVel>1</maxVel>
  <material>Gazebo/Black</material>
</gazebo>

<gazebo reference="left_front_wheel">
  <mu1>1</mu1>
  <mu2>1</mu2>
  <kp>100.0</kp>
  <kd>100.0</kd>
  <minDepth>0.001</minDepth>
  <maxVel>1</maxVel>
  <material>Gazebo/Black</material>
</gazebo>

<gazebo reference="right_front_wheel">
  <mu1>1</mu1>
  <mu2>1</mu2>
  <kp>100.0</kp>
  <kd>100.0</kd>
  <minDepth>0.001</minDepth>
  <maxVel>1</maxVel>
  <material>Gazebo/Black</material>
</gazebo>

<gazebo reference="right_center_wheel">
  <mu1>1</mu1>
  <mu2>1</mu2>
  <kp>100.0</kp>
  <kd>100.0</kd>
  <minDepth>0.001</minDepth>
  <maxVel>1</maxVel>
  <material>Gazebo/Black</material>
</gazebo>

<gazebo reference="right_back_wheel">
  <mu1>1</mu1>
  <mu2>1</mu2>
  <kp>100.0</kp>
  <kd>100.0</kd>
  <minDepth>0.001</minDepth>
  <maxVel>1</maxVel>
  <material>Gazebo/Black</material>
</gazebo> 

<gazebo reference="left_back_wheel_to_base_link">
  <mu1>1</mu1>
  <mu2>1</mu2>
  <kp>100.0</kp>
  <kd>100.0</kd>
  <minDepth>0.001</minDepth>
  <maxVel>1</maxVel>
  <material>Gazebo/Black</material>
</gazebo>

<gazebo reference="left_center_wheel_to_base_link">
  <mu1>1</mu1>
  <mu2>1</mu2>
  <kp>100.0</kp>
  <kd>100.0</kd>
  <minDepth>0.001</minDepth>
  <maxVel>1</maxVel>
  <material>Gazebo/Black</material>
</gazebo>

<gazebo reference="left_front_wheel_to_base_link">
  <mu1>1</mu1>
  <mu2>1</mu2>
  <kp>100.0</kp>
  <kd>100.0</kd>
  <minDepth>0.001</minDepth>
  <maxVel>1</maxVel>
  <material>Gazebo/Black</material>
</gazebo>

<gazebo reference="right_front_wheel_to_base_link">
  <mu1>1</mu1>
  <mu2>1</mu2>
  <kp>100.0</kp>
  <kd>100.0</kd>
  <minDepth>0.001</minDepth>
  <maxVel>1</maxVel>
  <material>Gazebo/Black</material>
</gazebo>

<gazebo reference="right_center_wheel_to_base_link">
  <mu1>1</mu1>
  <mu2>1</mu2>
  <kp>100.0</kp>
  <kd>100.0</kd>
  <minDepth>0.001</minDepth>
  <maxVel>1</maxVel>
  <material>Gazebo/Black</material>
</gazebo>

<gazebo reference="right_back_wheel_to_base_link">
  <mu1>1</mu1>
  <mu2>1</mu2>
  <kp>100.0</kp>
  <kd>100.0</kd>
  <minDepth>0.001</minDepth>
  <maxVel>1</maxVel>
  <material>Gazebo/Black</material>
</gazebo>

-->

<gazebo>
  <plugin name="center_differential_drive_controller" filename="libgazebo_ros_diff_drive.so">
    <legacyMode>false</legacyMode>
    <publishTf>1</publishTf>
    <publishWheelTF>true</publishWheelTF>
    <publishWheelJointState>true</publishWheelJointState>
    <alwaysOn>true</alwaysOn>
    <updateRate>50</updateRate>
    <leftJoint>left_center_wheel_to_base_link </leftJoint>
    <rightJoint>right_center_wheel_to_base_link</rightJoint>
    <wheelSeparation>0.52</wheelSeparation>
    <wheelDiameter>0.1</wheelDiameter>
    <wheelTorque>10</wheelTorque>
    <wheelAcceleration>3</wheelAcceleration>
    <commandTopic>/cmd_vel</commandTopic>
    <odometryTopic>/odom</odometryTopic>
    <odometryFrame>/odom</odometryFrame>
    <robotBaseFrame>base_link</robotBaseFrame>
  </plugin>

</gazebo>
<!-- <gazebo>
  <plugin name="front_differential_drive_controller" filename="libgazebo_ros_diff_drive.so">
    <legacyMode>false</legacyMode>
    <publishTf>1</publishTf>
    <publishWheelTF>true</publishWheelTF>
    <publishWheelJointState>true</publishWheelJointState>
    <alwaysOn>true</alwaysOn>
    <updateRate>50</updateRate>
    <leftJoint>left_front_wheel_to_base_link </leftJoint>
    <rightJoint>right_front_wheel_to_base_link</rightJoint>
    <wheelSeparation>0.52</wheelSeparation>
    <wheelDiameter>0.1</wheelDiameter>
    <wheelTorque>1</wheelTorque>
    <wheelAcceleration>3</wheelAcceleration>
    <commandTopic>/cmd_vel</commandTopic>
    <odometryTopic>/odom</odometryTopic>
    <odometryFrame>/odom</odometryFrame>
    <robotBaseFrame>base_link</robotBaseFrame>
    </plugin>

</gazebo> 
<gazebo>
  <plugin name="back_differential_drive_controller" filename="libgazebo_ros_diff_drive.so">
    <legacyMode>false</legacyMode>
    <publishTf>1</publishTf>
    <publishWheelTF>true</publishWheelTF>
    <publishWheelJointState>true</publishWheelJointState>
    <alwaysOn>true</alwaysOn>
    <updateRate>50</updateRate>
    <leftJoint>left_back_wheel_to_base_link </leftJoint>
    <rightJoint>right_back_wheel_to_base_link</rightJoint>
    <wheelSeparation>0.52</wheelSeparation>
    <wheelDiameter>0.1</wheelDiameter>
    <wheelTorque>10</wheelTorque>
    <wheelAcceleration>3</wheelAcceleration>
    <commandTopic>/cmd_vel</commandTopic>
    <odometryTopic>/odom</odometryTopic>
    <odometryFrame>/odom</odometryFrame>
    <robotBaseFrame>base_link</robotBaseFrame>
  </plugin>
</gazebo>

-->



</robot>
