<?xml version="1.0"?>
<robot name="myfirst" xmlns:xacro="http://www.ros.org/wiki/xacro">


  <material name="metal">
    <color rgba="0.35 0.35 0.35 2"/>
  </material>


  <material name="black">
    <color rgba="0.15 0.15 0.15 2"/>
  </material>


  <link name="base_link">
    <visual>
        <origin xyz="-0.31 0.47 0" rpy="1.57 0 0" />
        <geometry>
            <mesh filename="package://my_lib/src/simulation/Full Robot Late night.STL" scale="0.001 0.001 0.001" />
        </geometry>
        <material name="metal"/>
    </visual>

    <!-- <collision>
      <origin xyz="-0.31 0.47 0" rpy="1.57 0 0" />
      <geometry>
          <mesh filename="package://my_lib/src/simulation/Full Robot Late night.STL" scale="0.001 0.001 0.001" />
      </geometry>
    </collision> -->

    <inertial>
      <mass value="50.0"/>
      <inertia ixx="1.0" iyy="1.0" izz="1.0" ixy="0.0" ixz="0.0" iyz="0.0"/>
    </inertial>
  </link>




  <link name="left_center_wheel">
    <visual>
      <geometry>
        <cylinder length="0.05" radius="0.1"/>
      </geometry>
      <origin rpy="0 1.57076 0" xyz="0 0 0"/>
      <material name="black"/>
    </visual>

  <collision>
    <geometry>
      <cylinder length="0.05" radius="0.1"/>
    </geometry>
    <origin rpy="0 1.57076 0" xyz="0 0 0"/>
  </collision>

  <inertial>
    <mass value="0.5"/>
    <inertia ixx="1.0" iyy="1.0" izz="1.0" ixy="0.0" ixz="0.0" iyz="0.0"/>
  </inertial>
</link>


  <joint name="left_center_wheel_to_base_link" type="continuous">
    <parent link="base_link"/>
    <child link="left_center_wheel"/>
    <origin xyz="0.27 0 0.052" rpy="0 0 0"/>
    <axis xyz="1 0 0"/>
  </joint>



    <link name="left_front_wheel">
      <visual>
        <geometry>
          <cylinder length="0.05" radius="0.1"/>
        </geometry>
        <origin rpy="0 1.57076 0" xyz="0 0 0"/>
        <material name="black"/>
      </visual>

    <collision>
      <geometry>
        <cylinder length="0.05" radius="0.1"/>
      </geometry>
      <origin rpy="0 1.57076 0" xyz="0 0 0"/>
    </collision>

    <inertial>
      <mass value="0.5"/>
      <inertia ixx="1.0" iyy="1.0" izz="1.0" ixy="0.0" ixz="0.0" iyz="0.0"/>
    </inertial>
  </link>


    <joint name="left_front_wheel_to_base_link" type="continuous">
      <parent link="base_link"/>
      <child link="left_front_wheel"/>
      <origin xyz="0.27 -0.345 0.052" rpy="0 0 0"/>
      <axis xyz="1 0 0"/>
    </joint>


        <link name="left_back_wheel">
          <visual>
            <geometry>
              <cylinder length="0.05" radius="0.1"/>
            </geometry>
            <origin rpy="0 1.57076 0" xyz="0 0 0"/>
            <material name="black"/>
          </visual>

        <collision>
          <geometry>
            <cylinder length="0.05" radius="0.1"/>
          </geometry>
          <origin rpy="0 1.57076 0" xyz="0 0 0"/>
        </collision>

        <inertial>
          <mass value="0.5"/>
          <inertia ixx="1.0" iyy="1.0" izz="1.0" ixy="0.0" ixz="0.0" iyz="0.0"/>
        </inertial>
      </link>


        <joint name="left_back_wheel_to_base_link" type="continuous">
          <parent link="base_link"/>
          <child link="left_back_wheel"/>
          <origin xyz="0.27 0.345 0.052" rpy="0 0 0"/>
          <axis xyz="1 0 0"/>
        </joint>



      <link name="right_center_wheel">
        <visual>
          <geometry>
            <cylinder length="0.05" radius="0.1"/>
          </geometry>
          <origin rpy="0 1.57076 0" xyz="0 0 0"/>
          <material name="black"/>
        </visual>

      <collision>
        <geometry>
          <cylinder length="0.05" radius="0.1"/>
        </geometry>
        <origin rpy="0 1.57076 0" xyz="0 0 0"/>
      </collision>

      <inertial>
        <mass value="0.5"/>
        <inertia ixx="1.0" iyy="1.0" izz="1.0" ixy="0.0" ixz="0.0" iyz="0.0"/>
      </inertial>
    </link>


      <joint name="right_center_wheel_to_base_link" type="continuous">
        <parent link="base_link"/>
        <child link="right_center_wheel"/>
        <origin xyz="-0.27 0 0.052" rpy="0 0 0"/>
        <axis xyz="1 0 0"/>
      </joint>



        <link name="right_front_wheel">
          <visual>
            <geometry>
              <cylinder length="0.05" radius="0.1"/>
            </geometry>
            <origin rpy="0 1.57076 0" xyz="0 0 0"/>
            <material name="black"/>
          </visual>

        <collision>
          <geometry>
            <cylinder length="0.05" radius="0.1"/>
          </geometry>
          <origin rpy="0 1.57076 0" xyz="0 0 0"/>
        </collision>

        <inertial>
          <mass value="0.5"/>
          <inertia ixx="1.0" iyy="1.0" izz="1.0" ixy="0.0" ixz="0.0" iyz="0.0"/>
        </inertial>
      </link>


        <joint name="right_front_wheel_to_base_link" type="continuous">
          <parent link="base_link"/>
          <child link="right_front_wheel"/>
          <origin xyz="-0.27 -0.345 0.052" rpy="0 0 0"/>
          <axis xyz="1 0 0"/>
        </joint>


            <link name="right_back_wheel">
              <visual>
                <geometry>
                  <cylinder length="0.05" radius="0.1"/>
                </geometry>
                <origin rpy="0 1.57076 0" xyz="0 0 0"/>
                <material name="black"/>
              </visual>

            <collision>
              <geometry>
                <cylinder length="0.05" radius="0.1"/>
              </geometry>
              <origin rpy="0 1.57076 0" xyz="0 0 0"/>
            </collision>

            <inertial>
              <mass value="0.5"/>
              <inertia ixx="1.0" iyy="1.0" izz="1.0" ixy="0.0" ixz="0.0" iyz="0.0"/>
            </inertial>
          </link>


            <joint name="right_back_wheel_to_base_link" type="continuous">
              <parent link="base_link"/>
              <child link="right_back_wheel"/>
              <origin xyz="-0.27 0.345 0.052" rpy="0 0 0"/>
              <axis xyz="1 0 0"/>
            </joint>


        <link name="rails">
          <visual>
            <geometry>
              <box size="0.1 0.1 0.1"/>
            </geometry>
            <origin rpy="1.57 0 0" xyz="-0.091 0.287 -0.03"/>
            <material name="metal"/>
          </visual>

        <!-- <collision>
          <geometry>
            <mesh filename="package://my_lib/simulation/shiri rails.STL" scale="0.001 0.001 0.001" />
          </geometry>
          <origin rpy="1.57 0 0" xyz="-0.091 0.287 -0.03"/>
        </collision>

        <inertial>
          <mass value="1.0"/>
          <inertia ixx="0.0" ixy="0.0" ixz="0.0" iyy="0.0" iyz="0.0" izz="0.0"/>
        </inertial> -->
      </link>



      <joint name="rails_to_base_link" type="fixed">
        <parent link="base_link"/>
        <child link="rails"/>
        <origin xyz="0 0 0" rpy="0 0 0"/>
      </joint>



      <link name="shiri_head">
        <visual>
          <geometry>
            <mesh filename="package://my_lib/simulation/shiri head.STL" scale="0.001 0.001 0.001" />
          </geometry>
          <origin rpy="1.57 0 0" xyz="-0.14 0 -0.0275"/>
          <material name="metal"/>
        </visual>
<!--
      <collision>
        <geometry>
          <mesh filename="package://my_lib/simulation/shiri head.STL" scale="0.001 0.001 0.001" />
        </geometry>
        <origin rpy="1.57 0 0" xyz="-0.14 0 -0.0275"/>
      </collision>

      <inertial>
        <mass value="1.0"/>
        <inertia ixx="0.0" ixy="0.0" ixz="0.0" iyy="0.0" iyz="0.0" izz="0.0"/>
      </inertial> -->
    </link>



    <joint name="shiri_head_to_rails" type="fixed">
      <parent link="rails"/>
      <child link="shiri_head"/>
      <origin xyz="0 0 0" rpy="0 0 0"/>
    </joint>



    <link name="tower">
      <visual>
        <geometry>
          <mesh filename="package://my_lib/src/simulation/2230-2019-Lift.STL" scale="0.001 0.001 0.001" />
        </geometry>
        <origin rpy="1.57 0 1.57" xyz="-0.2 0.16 0.215"/>
        <material name="metal"/>
      </visual>

    <!-- <collision>
      <geometry>
        <mesh filename="package://my_lib/simulation/2230-2019-Lift-A0000-S.STL" scale="0.001 0.001 0.001" />
      </geometry>
      <origin rpy="1.57 0 1.57" xyz="-0.2 0.16 0.215"/>
    </collision>

    <inertial>
      <mass value="4.0"/>
      <inertia ixx="0.0" ixy="0.0" ixz="0.0" iyy="0.0" iyz="0.0" izz="0.0"/>
    </inertial> -->
  </link>



  <joint name="tower_to_base_link" type="fixed">
    <parent link="base_link"/>
    <child link="tower"/>
    <origin xyz="0 0 0" rpy="0 0 0"/>
  </joint>



<!--

  <link name="arm">
    <visual>
      <geometry>
        <box size="1.22 0.0254 0.0254"/>
      </geometry>
      <origin rpy="0 0 1.57" xyz="0.0 0.0 0"/>
      <material name="metal"/>
    </visual>

  <collision>
    <geometry>
      <box size="1.22 0.0254 0.0254"/>
    </geometry>
    <origin rpy="0 0 1.57" xyz="0.0 0.0 0"/>
  </collision>
<!
  <inertial>
    <mass value="4.0"/>
    <inertia ixx="0.0" ixy="0.0" ixz="0.0" iyy="0.0" iyz="0.0" izz="0.0"/>
  </inertial> >
</link>

<joint name="arm_to_tower" type="fixed">
  <parent link="tower"/>
  <child link="arm"/>
  <origin xyz="0 0.36 1.03" rpy="0 0 0"/>
  <axis xyz="1 0 0"/>
</joint>



  <link name="sylinder">
    <visual>
      <geometry>
        <mesh filename="package://my_lib/src/simulation/tomer sylinder.STL" scale="0.001 0.001 0.001" />
      </geometry>
      <origin rpy="1.57 0 1.57" xyz="-0.18 -0.15 -0.23"/>
      <material name="metal"/>
    </visual>
  </link>
  <joint name="sylinder_to_arm" type="fixed">
    <parent link="arm"/>
    <child link="sylinder"/>
    <origin xyz="0 -0.6 0" rpy="0 0 0"/>
    <axis xyz="1 0 0"/>
  </joint>

  <link name="fingers_holder">
    <visual>
      <geometry>
        <box size="0.01 0.01 0.01"/>
      </geometry>
      <origin rpy="0 0 0" xyz="0 0 0"/>
      <material name="metal"/>
    </visual>
  </link>

  <joint name="fingers_holder_to_sylinder" type="fixed">
    <parent link="sylinder"/>
    <child link="fingers_holder"/>
    <origin xyz="0 -0.08 -0.07" rpy="0 0 0"/>
    <axis xyz="0 0 0"/>
  </joint>

  <link name="lb_finger">
      <visual>
        <geometry>
          <mesh filename="package://my_lib/src/simulation/tomer finger.STL" scale="0.001 0.001 0.001" />
        </geometry>
        <origin xyz="0.15 -0.31 -0.2" rpy="0 0 1.57"/>
        <material name="metal"/>
      </visual>


  <joint name="lb_finger_joint" type="fixed">
    <parent link="fingers_holder"/>
    <child link="lb_finger"/>
    <origin xyz="0 0 0" rpy="0 0.43 0"/>
    <axis xyz="1 0 0"/>
  </joint>

  <link name="ru_finger">
      <visual>
        <geometry>
          <mesh filename="package://my_lib/src/simulation/tomer finger.STL" scale="0.001 0.001 0.001" />
        </geometry>
        <origin rpy="0 0 1.57" xyz="0.15 -0.31 -0.2"/>
        <material name="metal"/>
      </visual>

  </link>

  <joint name="ru_finger_joint" type="fixed">
    <parent link="fingers_holder"/>
    <child link="ru_finger"/>
    <origin xyz="0 0 0" rpy="0 -2.65 0"/>
    <axis xyz="1 0 0"/>
  </joint>

  <link name="lu_finger">
      <visual>
        <geometry>
          <mesh filename="package://my_lib/src/simulation/tomer finger.STL" scale="0.001 0.001 0.001" />
        </geometry>
        <origin rpy="0 0 1.57" xyz="0.15 -0.31 -0.2"/>
        <material name="metal"/>
      </visual>
    <collision>
      <geometry>
        <mesh filename="package://my_lib/src/simulation/tomer finger.STL" scale="0.001 0.001 0.001" />
      </geometry>
      <origin rpy="0 0 1.57" xyz="0.15 -0.31 -0.2"/>
    </collision>
  </link>

  <joint name="lu_finger_joint" type="fixed">
    <parent link="fingers_holder"/>
    <child link="lu_finger"/>
    <origin xyz="0 0 0" rpy="0 1.64 0"/>
    <axis xyz="1 0 0"/>
  </joint>



    <link name="rb_finger">
        <visual>
          <geometry>
            <mesh filename="package://my_lib/src/simulation/tomer finger.STL" scale="0.001 0.001 0.001" />
          </geometry>
          <origin rpy="0 0 1.57" xyz="0.15 -0.31 -0.2"/>
          <material name="metal"/>
        </visual>

    </link>

    <joint name="rb_finger_joint" type="fixed">
      <parent link="fingers_holder"/>
      <child link="rb_finger"/>
      <origin xyz="0 0 0" rpy="0 -1.6 0"/>
      <axis xyz="1 0 0"/>
    </joint> -->


<!-- gazebo pluings -->
<gazebo reference="base_link">
  <mu1>0.5</mu1>
  <mu2>0.5</mu2>
  <material>Gazebo/White</material>
</gazebo>
<!--
<gazebo reference="left_back_wheel">
  <mu1>1</mu1>
  <mu2>1</mu2>
  <kp>100.0</kp>
  <kd>100.0</kd>
  <minDepth>0.001</minDepth>
  <maxVel>1</maxVel>
  <material>Gazebo/Black</material>
</gazebo>

<gazebo reference="left_center_wheel">
  <mu1>1</mu1>
  <mu2>1</mu2>
  <kp>100.0</kp>
  <kd>100.0</kd>
  <minDepth>0.001</minDepth>
  <maxVel>1</maxVel>
  <material>Gazebo/Black</material>
</gazebo>

<gazebo reference="left_front_wheel">
  <mu1>1</mu1>
  <mu2>1</mu2>
  <kp>100.0</kp>
  <kd>100.0</kd>
  <minDepth>0.001</minDepth>
  <maxVel>1</maxVel>
  <material>Gazebo/Black</material>
</gazebo>

<gazebo reference="right_front_wheel">
  <mu1>1</mu1>
  <mu2>1</mu2>
  <kp>100.0</kp>
  <kd>100.0</kd>
  <minDepth>0.001</minDepth>
  <maxVel>1</maxVel>
  <material>Gazebo/Black</material>
</gazebo>

<gazebo reference="right_center_wheel">
  <mu1>1</mu1>
  <mu2>1</mu2>
  <kp>100.0</kp>
  <kd>100.0</kd>
  <minDepth>0.001</minDepth>
  <maxVel>1</maxVel>
  <material>Gazebo/Black</material>
</gazebo>

<gazebo reference="right_back_wheel">
  <mu1>1</mu1>
  <mu2>1</mu2>
  <kp>100.0</kp>
  <kd>100.0</kd>
  <minDepth>0.001</minDepth>
  <maxVel>1</maxVel>
  <material>Gazebo/Black</material>
</gazebo> -->

<gazebo reference="left_back_wheel_to_base_link">
  <mu1>1</mu1>
  <mu2>1</mu2>
  <kp>100.0</kp>
  <kd>100.0</kd>
  <minDepth>0.001</minDepth>
  <maxVel>1</maxVel>
  <material>Gazebo/Black</material>
</gazebo>

<gazebo reference="left_center_wheel_to_base_link">
  <mu1>1</mu1>
  <mu2>1</mu2>
  <kp>100.0</kp>
  <kd>100.0</kd>
  <minDepth>0.001</minDepth>
  <maxVel>1</maxVel>
  <material>Gazebo/Black</material>
</gazebo>

<gazebo reference="left_front_wheel_to_base_link">
  <mu1>1</mu1>
  <mu2>1</mu2>
  <kp>100.0</kp>
  <kd>100.0</kd>
  <minDepth>0.001</minDepth>
  <maxVel>1</maxVel>
  <material>Gazebo/Black</material>
</gazebo>

<gazebo reference="right_front_wheel_to_base_link">
  <mu1>1</mu1>
  <mu2>1</mu2>
  <kp>100.0</kp>
  <kd>100.0</kd>
  <minDepth>0.001</minDepth>
  <maxVel>1</maxVel>
  <material>Gazebo/Black</material>
</gazebo>

<gazebo reference="right_center_wheel_to_base_link">
  <mu1>1</mu1>
  <mu2>1</mu2>
  <kp>100.0</kp>
  <kd>100.0</kd>
  <minDepth>0.001</minDepth>
  <maxVel>1</maxVel>
  <material>Gazebo/Black</material>
</gazebo>

<gazebo reference="right_back_wheel_to_base_link">
  <mu1>1</mu1>
  <mu2>1</mu2>
  <kp>100.0</kp>
  <kd>100.0</kd>
  <minDepth>0.001</minDepth>
  <maxVel>1</maxVel>
  <material>Gazebo/Black</material>
</gazebo>


<gazebo>
  <plugin name="center_differential_drive_controller" filename="libgazebo_ros_diff_drive.so">
    <legacyMode>false</legacyMode>
    <publishTf>1</publishTf>
    <publishWheelTF>true</publishWheelTF>
    <publishWheelJointState>true</publishWheelJointState>
    <alwaysOn>true</alwaysOn>
    <updateRate>50</updateRate>
    <leftJoint>left_center_wheel_to_base_link </leftJoint>
    <rightJoint>right_center_wheel_to_base_link</rightJoint>
    <wheelSeparation>0.52</wheelSeparation>
    <wheelDiameter>0.1</wheelDiameter>
    <wheelTorque>10</wheelTorque>
    <wheelAcceleration>3</wheelAcceleration>
    <commandTopic>/cmd_vel</commandTopic>
    <odometryTopic>/odom</odometryTopic>
    <odometryFrame>/odom</odometryFrame>
    <robotBaseFrame>base_link</robotBaseFrame>
  </plugin>

</gazebo>
<!-- <gazebo>
  <plugin name="front_differential_drive_controller" filename="libgazebo_ros_diff_drive.so">
    <legacyMode>false</legacyMode>
    <publishTf>1</publishTf>
    <publishWheelTF>true</publishWheelTF>
    <publishWheelJointState>true</publishWheelJointState>
    <alwaysOn>true</alwaysOn>
    <updateRate>50</updateRate>
    <leftJoint>left_front_wheel_to_base_link </leftJoint>
    <rightJoint>right_front_wheel_to_base_link</rightJoint>
    <wheelSeparation>0.52</wheelSeparation>
    <wheelDiameter>0.1</wheelDiameter>
    <wheelTorque>1</wheelTorque>
    <wheelAcceleration>3</wheelAcceleration>
    <commandTopic>/cmd_vel</commandTopic>
    <odometryTopic>/odom</odometryTopic>
    <odometryFrame>/odom</odometryFrame>
    <robotBaseFrame>base_link</robotBaseFrame>
    </plugin>

</gazebo> -->
<gazebo>
  <plugin name="back_differential_drive_controller" filename="libgazebo_ros_diff_drive.so">
    <legacyMode>false</legacyMode>
    <publishTf>1</publishTf>
    <publishWheelTF>true</publishWheelTF>
    <publishWheelJointState>true</publishWheelJointState>
    <alwaysOn>true</alwaysOn>
    <updateRate>50</updateRate>
    <leftJoint>left_back_wheel_to_base_link </leftJoint>
    <rightJoint>right_back_wheel_to_base_link</rightJoint>
    <wheelSeparation>0.52</wheelSeparation>
    <wheelDiameter>0.1</wheelDiameter>
    <wheelTorque>10</wheelTorque>
    <wheelAcceleration>3</wheelAcceleration>
    <commandTopic>/cmd_vel</commandTopic>
    <odometryTopic>/odom</odometryTopic>
    <odometryFrame>/odom</odometryFrame>
    <robotBaseFrame>base_link</robotBaseFrame>
  </plugin>
</gazebo>





</robot>
